源码
[root@k8s-master-1 ~]# grep compute_driver /etc/nova/nova.conf
#compute_driver=libvirt.LibvirtDriver
# * ``compute_driver``: Only the libvirt driver uses this option.
# * ``compute_driver``: Must be hyperv.
# * compute_driver: Must use vmwareapi.VMwareVCDriver.
# * ``compute_driver`` (libvirt)
# * ``compute_driver``: Only the libvirt driver is affected.
# XenServer options are used when the compute_driver is set to use
# XenServer (compute_driver=xenapi.XenAPIDriver).
# use compute_driver=xenapi.XenAPIDriver.
# * ``compute_driver`` should be set to ``xenapi.XenAPIDriver``



问题
ERROR nova.compute.resource_tracker [req-153f4f0b-b2d4-428c-8306-43f84ebf1e08 - - - - -] Migration for instance 9ad55985-3319-4f6e-b01c-d40e9341f782 refers to another host's instance!

    <channel type='unix'>
      <source mode='bind' path='/var/lib/libvirt/qemu/org.qemu.guest_agent.0.instance-00000025.sock'/>
      <target type='virtio' name='org.qemu.guest_agent.0' state='disconnected'/>
      <alias name='channel0'/>
      <address type='virtio-serial' controller='0' bus='0' port='1'/>
    </channel>

为解决








[Thu Nov 28 19:45:32.799537 2019] [:error] [pid 14021] INFO openstack_auth.plugin.base Attempted scope to domain default failed, will attemptto scope to another domain.
[Thu Nov 28 19:45:33.027968 2019] [:error] [pid 14021] INFO openstack_auth.forms Login successful for user "admin" using domain "default", remote address 192.168.80.67.
[Thu Nov 28 19:45:34.917370 2019] [:error] [pid 14021] ERROR django.request Internal Server Error: /dashboard/auth/login/
[Thu Nov 28 19:45:34.917410 2019] [:error] [pid 14021] Traceback (most recent call last):
[Thu Nov 28 19:45:34.917412 2019] [:error] [pid 14021]   File "/usr/lib/python2.7/site-packages/django/core/handlers/exception.py", line 41, in inner
[Thu Nov 28 19:45:34.917414 2019] [:error] [pid 14021]     response = get_response(request)
[Thu Nov 28 19:45:34.917416 2019] [:error] [pid 14021]   File "/usr/lib/python2.7/site-packages/django/core/handlers/base.py", line 249, in _legacy_get_response
[Thu Nov 28 19:45:34.917420 2019] [:error] [pid 14021]     response = self._get_response(request)
[Thu Nov 28 19:45:34.917421 2019] [:error] [pid 14021]   File "/usr/lib/python2.7/site-packages/django/core/handlers/base.py", line 187, in _get_response
[Thu Nov 28 19:45:34.917423 2019] [:error] [pid 14021]     response = self.process_exception_by_middleware(e, request)
[Thu Nov 28 19:45:34.917424 2019] [:error] [pid 14021]   File "/usr/lib/python2.7/site-packages/django/core/handlers/base.py", line 185, in _get_response
[Thu Nov 28 19:45:34.917427 2019] [:error] [pid 14021]     response = wrapped_callback(request, *callback_args, **callback_kwargs)
[Thu Nov 28 19:45:34.917429 2019] [:error] [pid 14021]   File "/usr/lib/python2.7/site-packages/django/views/decorators/debug.py", line 76, in sensitive_post_parameters_wrapper
[Thu Nov 28 19:45:34.917440 2019] [:error] [pid 14021]     return view(request, *args, **kwargs)
[Thu Nov 28 19:45:34.917442 2019] [:error] [pid 14021]   File "/usr/lib/python2.7/site-packages/django/utils/decorators.py", line 149, in _wrapped_view
[Thu Nov 28 19:45:34.917444 2019] [:error] [pid 14021]     response = view_func(request, *args, **kwargs)
[Thu Nov 28 19:45:34.917445 2019] [:error] [pid 14021]   File "/usr/lib/python2.7/site-packages/django/views/decorators/cache.py", line 57, in _wrapped_view_func
[Thu Nov 28 19:45:34.917447 2019] [:error] [pid 14021]     response = view_func(request, *args, **kwargs)
[Thu Nov 28 19:45:34.917448 2019] [:error] [pid 14021]   File "/usr/lib/python2.7/site-packages/openstack_auth/views.py", line 106, in login
[Thu Nov 28 19:45:34.917450 2019] [:error] [pid 14021]     **kwargs)
[Thu Nov 28 19:45:34.917451 2019] [:error] [pid 14021]   File "/usr/lib/python2.7/site-packages/django/contrib/auth/views.py", line 54, in inner
[Thu Nov 28 19:45:34.917452 2019] [:error] [pid 14021]     return func(*args, **kwargs)
[Thu Nov 28 19:45:34.917454 2019] [:error] [pid 14021]   File "/usr/lib/python2.7/site-packages/django/contrib/auth/views.py", line 150, in login
[Thu Nov 28 19:45:34.917456 2019] [:error] [pid 14021]     )(request)
[Thu Nov 28 19:45:34.917457 2019] [:error] [pid 14021]   File "/usr/lib/python2.7/site-packages/django/views/generic/base.py", line 68, in view
[Thu Nov 28 19:45:34.917463 2019] [:error] [pid 14021]     return self.dispatch(request, *args, **kwargs)
[Thu Nov 28 19:45:34.917465 2019] [:error] [pid 14021]   File "/usr/lib/python2.7/site-packages/django/utils/decorators.py", line 67, in _wrapper
[Thu Nov 28 19:45:34.917467 2019] [:error] [pid 14021]     return bound_func(*args, **kwargs)
[Thu Nov 28 19:45:34.917484 2019] [:error] [pid 14021]   File "/usr/lib/python2.7/site-packages/django/views/decorators/debug.py", line 76, in sensitive_post_parameters_wrapper
[Thu Nov 28 19:45:34.917504 2019] [:error] [pid 14021]     return view(request, *args, **kwargs)
[Thu Nov 28 19:45:34.917507 2019] [:error] [pid 14021]   File "/usr/lib/python2.7/site-packages/django/utils/decorators.py", line 63, in bound_func
[Thu Nov 28 19:45:34.917509 2019] [:error] [pid 14021]     return func.__get__(self, type(self))(*args2, **kwargs2)
[Thu Nov 28 19:45:34.917511 2019] [:error] [pid 14021]   File "/usr/lib/python2.7/site-packages/django/utils/decorators.py", line 67, in _wrapper
[Thu Nov 28 19:45:34.917513 2019] [:error] [pid 14021]     return bound_func(*args, **kwargs)
[Thu Nov 28 19:45:34.917515 2019] [:error] [pid 14021]   File "/usr/lib/python2.7/site-packages/django/utils/decorators.py", line 149, in _wrapped_view
[Thu Nov 28 19:45:34.917517 2019] [:error] [pid 14021]     response = view_func(request, *args, **kwargs)
[Thu Nov 28 19:45:34.917519 2019] [:error] [pid 14021]   File "/usr/lib/python2.7/site-packages/django/utils/decorators.py", line 63, in bound_func
[Thu Nov 28 19:45:34.917521 2019] [:error] [pid 14021]     return func.__get__(self, type(self))(*args2, **kwargs2)
[Thu Nov 28 19:45:34.917522 2019] [:error] [pid 14021]   File "/usr/lib/python2.7/site-packages/django/utils/decorators.py", line 67, in _wrapper
[Thu Nov 28 19:45:34.917524 2019] [:error] [pid 14021]     return bound_func(*args, **kwargs)
[Thu Nov 28 19:45:34.917526 2019] [:error] [pid 14021]   File "/usr/lib/python2.7/site-packages/django/views/decorators/cache.py", line 57, in _wrapped_view_func
[Thu Nov 28 19:45:34.917528 2019] [:error] [pid 14021]     response = view_func(request, *args, **kwargs)
[Thu Nov 28 19:45:34.917530 2019] [:error] [pid 14021]   File "/usr/lib/python2.7/site-packages/django/utils/decorators.py", line 63, in bound_func
[Thu Nov 28 19:45:34.917532 2019] [:error] [pid 14021]     return func.__get__(self, type(self))(*args2, **kwargs2)
[Thu Nov 28 19:45:34.917534 2019] [:error] [pid 14021]   File "/usr/lib/python2.7/site-packages/django/contrib/auth/views.py", line 90, in dispatch
[Thu Nov 28 19:45:34.917541 2019] [:error] [pid 14021]     return super(LoginView, self).dispatch(request, *args, **kwargs)
[Thu Nov 28 19:45:34.917543 2019] [:error] [pid 14021]   File "/usr/lib/python2.7/site-packages/django/views/generic/base.py", line 88, in dispatch
[Thu Nov 28 19:45:34.917545 2019] [:error] [pid 14021]     return handler(request, *args, **kwargs)
[Thu Nov 28 19:45:34.917547 2019] [:error] [pid 14021]   File "/usr/lib/python2.7/site-packages/django/views/generic/edit.py", line 183, in post
[Thu Nov 28 19:45:34.917549 2019] [:error] [pid 14021]     return self.form_valid(form)
[Thu Nov 28 19:45:34.917551 2019] [:error] [pid 14021]   File "/usr/lib/python2.7/site-packages/django/contrib/auth/views.py", line 119, in form_valid
[Thu Nov 28 19:45:34.917553 2019] [:error] [pid 14021]     auth_login(self.request, form.get_user())
[Thu Nov 28 19:45:34.917555 2019] [:error] [pid 14021]   File "/usr/lib/python2.7/site-packages/django/contrib/auth/__init__.py", line 140, in login
[Thu Nov 28 19:45:34.917557 2019] [:error] [pid 14021]     request.session.cycle_key()
[Thu Nov 28 19:45:34.917559 2019] [:error] [pid 14021]   File "/usr/lib/python2.7/site-packages/django/contrib/sessions/backends/base.py", line 311, in cycle_key
[Thu Nov 28 19:45:34.917561 2019] [:error] [pid 14021]     self.create()
[Thu Nov 28 19:45:34.917562 2019] [:error] [pid 14021]   File "/usr/lib/python2.7/site-packages/django/contrib/sessions/backends/cache.py", line 52, in create
[Thu Nov 28 19:45:34.917564 2019] [:error] [pid 14021]     "Unable to create a new session key. "
[Thu Nov 28 19:45:34.917566 2019] [:error] [pid 14021] RuntimeError: Unable to create a new session key. It is likely that the cache is unavailable.













2019-11-22 13:02:55.037 21160 INFO nova.api.openstack.wsgi [req-283ae40c-d29b-499d-84fd-87ff11eadc8b 4a44f9caaf2045d691354dce782ddb3e fa689ffe41cb46fb9a039bff9102debf - default default] HTTP exception thrown: Image b351c511-b6e5-4777-bae4-006047c7149f is unacceptable: Unable to rebuild with a different image for a volume-backed server.
2019-11-22 13:02:55.039 21160 INFO nova.osapi_compute.wsgi.server [req-283ae40c-d29b-499d-84fd-87ff11eadc8b 4a44f9caaf2045d691354dce782ddb3e fa689ffe41cb46fb9a039bff9102debf - default default] 192.168.110.72 "POST /v2.1/servers/3578bb0a-b8a7-4c53-96d9-96fa1f8816a5/action HTTP/1.1" status: 400 len: 595 time: 0.2873561
2019-11-22 13:02:55.110 21160 INFO nova.osapi_compute.wsgi.server [req-23c5ea93-56fe-42be-8c0f-27a26c719418 4a44f9caaf2045d691354dce782ddb3e fa689ffe41cb46fb9a039bff9102debf - default default] 192.168.110.72 "GET /v2.1/flavors/detail HTTP/1.1" status: 200 len: 2282 time: 0.0331519
2019-11-22 13:02:55.149 21160 INFO nova.osapi_compute.wsgi.server [req-ee420e5e-8195-45da-b7dc-9959870985c1 4a44f9caaf2045d691354dce782ddb3e fa689ffe41cb46fb9a039bff9102debf - default default] 192.168.110.72 "GET /v2.1 HTTP/1.1" status: 302 len: 319 time: 0.0054340
2019-11-22 13:02:55.158 21160 INFO nova.osapi_compute.wsgi.server [req-f9c957ac-f6f7-4711-b90f-75baea5e794e 4a44f9caaf2045d691354dce782ddb3e fa689ffe41cb46fb9a039bff9102debf - default default] 192.168.110.72 "GET /v2.1/ HTTP/1.1" status: 200 len: 790 time: 0.0055900
2019-11-22 13:02:56.772 21177 INFO nova.osapi_compute.wsgi.server [req-6bb16cdf-833e-4497-976a-97bea76b49b6 4a44f9caaf2045d691354dce782ddb3e fa689ffe41cb46fb9a039bff9102debf - default default] 192.168.80.167 "POST /v2.1/fa689ffe41cb46fb9a039bff9102debf/servers/115b717a-b965-4b60-946d-746e98f85797/action HTTP/1.1" status: 200 len: 24836 time: 0.1290369
2019-11-22 13:02:56.833 21162 INFO nova.osapi_compute.wsgi.server [req-7a7be5e8-74d5-4e91-aaa8-d86456b751d7 4a44f9caaf2045d691354dce782ddb3e fa689ffe41cb46fb9a039bff9102debf - default default] 192.168.110.72 "GET /v2.1/servers/detail?limit=21&project_id=fa689ffe41cb46fb9a039bff9102debf HTTP/1.1" status: 200 len: 15391 time: 1.3117881
2019-11-22 13:02:57.464 21160 INFO nova.osapi_compute.wsgi.server [req-d19696ce-92c1-4d69-be73-48ad8ed513ee 4a44f9caaf2045d691354dce782ddb3e fa689ffe41cb46fb9a039bff9102debf - default default] 192.168.110.72 "GET /v2.1/limits?reserved=1 HTTP/1.1" status: 200 len: 915 time: 0.0761569
2019-11-22 13:02:57.841 21160 INFO nova.osapi_compute.wsgi.server [req-93bf7a0a-8d5c-40f0-b165-4e4221088223 4a44f9caaf2045d691354dce782ddb3e fa689ffe41cb46fb9a039bff9102debf - default default] 192.168.110.72 "GET /v2.1/limits?reserved=1 HTTP/1.1" status: 200 len: 915 time: 0.0729160

S版解决



2019-11-22 11:11:13.953 12946 WARNING nova.compute.manager [req-16dbfdc5-ed2b-4184-b2d9-b9a522e16cf5 4a44f9caaf2045d691354dce782ddb3e fa689ffe41cb46fb9a039bff9102debf - default default] [instance: 629a1603-6cd3-45a9-988c-c4a9939715c8] set_admin_password is not implemented by this driver or guest instance.: NotImplementedError
2019-11-22 11:11:14.401 12946 INFO nova.compute.manager [req-16dbfdc5-ed2b-4184-b2d9-b9a522e16cf5 4a44f9caaf2045d691354dce782ddb3e fa689ffe41cb46fb9a039bff9102debf - default default] [instance: 629a1603-6cd3-45a9-988c-c4a9939715c8] Successfully reverted task state from None on failure for instance.
2019-11-22 11:11:14.412 12946 ERROR oslo_messaging.rpc.server [req-16dbfdc5-ed2b-4184-b2d9-b9a522e16cf5 4a44f9caaf2045d691354dce782ddb3e fa689ffe41cb46fb9a039bff9102debf - default default] Exception during message handling: NotImplementedError: set_admin_password is not implemented by this driver or guest instance.
2019-11-22 11:11:14.412 12946 ERROR oslo_messaging.rpc.server Traceback (most recent call last):
2019-11-22 11:11:14.412 12946 ERROR oslo_messaging.rpc.server   File "/usr/lib/python2.7/site-packages/oslo_messaging/rpc/server.py", line 166, in _process_incoming
2019-11-22 11:11:14.412 12946 ERROR oslo_messaging.rpc.server     res = self.dispatcher.dispatch(message)
2019-11-22 11:11:14.412 12946 ERROR oslo_messaging.rpc.server   File "/usr/lib/python2.7/site-packages/oslo_messaging/rpc/dispatcher.py", line 220, in dispatch
2019-11-22 11:11:14.412 12946 ERROR oslo_messaging.rpc.server     return self._do_dispatch(endpoint, method, ctxt, args)
2019-11-22 11:11:14.412 12946 ERROR oslo_messaging.rpc.server   File "/usr/lib/python2.7/site-packages/oslo_messaging/rpc/dispatcher.py", line 190, in _do_dispatch
2019-11-22 11:11:14.412 12946 ERROR oslo_messaging.rpc.server     result = func(ctxt, **new_args)
2019-11-22 11:11:14.412 12946 ERROR oslo_messaging.rpc.server   File "/usr/lib/python2.7/site-packages/nova/exception_wrapper.py", line 76, in wrapped
2019-11-22 11:11:14.412 12946 ERROR oslo_messaging.rpc.server     function_name, call_dict, binary)
2019-11-22 11:11:14.412 12946 ERROR oslo_messaging.rpc.server   File "/usr/lib/python2.7/site-packages/oslo_utils/excutils.py", line 220, in __exit__
2019-11-22 11:11:14.412 12946 ERROR oslo_messaging.rpc.server     self.force_reraise()
2019-11-22 11:11:14.412 12946 ERROR oslo_messaging.rpc.server   File "/usr/lib/python2.7/site-packages/oslo_utils/excutils.py", line 196, in force_reraise
2019-11-22 11:11:14.412 12946 ERROR oslo_messaging.rpc.server     six.reraise(self.type_, self.value, self.tb)
2019-11-22 11:11:14.412 12946 ERROR oslo_messaging.rpc.server   File "/usr/lib/python2.7/site-packages/nova/exception_wrapper.py", line 67, in wrapped
2019-11-22 11:11:14.412 12946 ERROR oslo_messaging.rpc.server     return f(self, context, *args, **kw)
2019-11-22 11:11:14.412 12946 ERROR oslo_messaging.rpc.server   File "/usr/lib/python2.7/site-packages/nova/compute/manager.py", line 187, in decorated_function
2019-11-22 11:11:14.412 12946 ERROR oslo_messaging.rpc.server     "Error: %s", e, instance=instance)
2019-11-22 11:11:14.412 12946 ERROR oslo_messaging.rpc.server   File "/usr/lib/python2.7/site-packages/oslo_utils/excutils.py", line 220, in __exit__
2019-11-22 11:11:14.412 12946 ERROR oslo_messaging.rpc.server     self.force_reraise()
2019-11-22 11:11:14.412 12946 ERROR oslo_messaging.rpc.server   File "/usr/lib/python2.7/site-packages/oslo_utils/excutils.py", line 196, in force_reraise
2019-11-22 11:11:14.412 12946 ERROR oslo_messaging.rpc.server     six.reraise(self.type_, self.value, self.tb)
2019-11-22 11:11:14.412 12946 ERROR oslo_messaging.rpc.server   File "/usr/lib/python2.7/site-packages/nova/compute/manager.py", line 157, in decorated_function
2019-11-22 11:11:14.412 12946 ERROR oslo_messaging.rpc.server     return function(self, context, *args, **kwargs)
2019-11-22 11:11:14.412 12946 ERROR oslo_messaging.rpc.server   File "/usr/lib/python2.7/site-packages/nova/compute/utils.py", line 1000, in decorated_function
2019-11-22 11:11:14.412 12946 ERROR oslo_messaging.rpc.server     return function(self, context, *args, **kwargs)
2019-11-22 11:11:14.412 12946 ERROR oslo_messaging.rpc.server   File "/usr/lib/python2.7/site-packages/nova/compute/manager.py", line 215, in decorated_function
2019-11-22 11:11:14.412 12946 ERROR oslo_messaging.rpc.server     kwargs['instance'], e, sys.exc_info())
2019-11-22 11:11:14.412 12946 ERROR oslo_messaging.rpc.server   File "/usr/lib/python2.7/site-packages/oslo_utils/excutils.py", line 220, in __exit__
2019-11-22 11:11:14.412 12946 ERROR oslo_messaging.rpc.server     self.force_reraise()
2019-11-22 11:11:14.412 12946 ERROR oslo_messaging.rpc.server   File "/usr/lib/python2.7/site-packages/oslo_utils/excutils.py", line 196, in force_reraise
2019-11-22 11:11:14.412 12946 ERROR oslo_messaging.rpc.server     six.reraise(self.type_, self.value, self.tb)
2019-11-22 11:11:14.412 12946 ERROR oslo_messaging.rpc.server   File "/usr/lib/python2.7/site-packages/nova/compute/manager.py", line 203, in decorated_function
2019-11-22 11:11:14.412 12946 ERROR oslo_messaging.rpc.server     return function(self, context, *args, **kwargs)
2019-11-22 11:11:14.412 12946 ERROR oslo_messaging.rpc.server   File "/usr/lib/python2.7/site-packages/nova/compute/manager.py", line 3540, in set_admin_password
2019-11-22 11:11:14.412 12946 ERROR oslo_messaging.rpc.server     raise NotImplementedError(_('set_admin_password is not '
2019-11-22 11:11:14.412 12946 ERROR oslo_messaging.rpc.server NotImplementedError: set_admin_password is not implemented by this driver or guest instance.
2019-11-22 11:11:14.412 12946 ERROR oslo_messaging.rpc.server
2019-11-22 11:12:01.240 12946 INFO nova.compute.resource_tracker [req-c6cc6fa0-c30e-4fa8-bd12-ca75d9162e7a - - - - -] Final resource view: name=k8s-node-2 phys_ram=32759MB used_ram=2560MB phys_disk=5585GB used_disk=100GB total_vcpus=16 used_vcpus=2 pci_stats=[]
2019-11-22 11:13:01.265 12946 INFO nova.compute.resource_tracker [req-c6cc6fa0-c30e-4fa8-bd12-ca75d9162e7a - - - - -] Final resource view: name=k8s-node-2 phys_ram=32759MB used_ram=2560MB phys_disk=5585GB used_disk=100GB total_vcpus=16 used_vcpus=2 pci_stats=[]
2019-11-22 11:14:03.248 12946 INFO nova.compute.resource_tracker [req-c6cc6fa0-c30e-4fa8-bd12-ca75d9162e7a - - - - -] Final resource view: name=k8s-node-2 phys_ram=32759MB used_ram=2560MB phys_disk=5585GB used_disk=100GB total_vcpus=16 used_vcpus=2 pci_stats=[]
2019-11-22 11:15:05.243 12946 INFO nova.compute.resource_tracker [req-c6cc6fa0-c30e-4fa8-bd12-ca75d9162e7a - - - - -] Final resource view: name=k8s-node-2 phys_ram=32759MB used_ram=2560MB phys_disk=5585GB used_disk=100GB total_vcpus=16 used_vcpus=2 pci_stats=[]
2019-11-22 11:15:17.100 12946 INFO nova.compute.manager [req-40511df5-a6ee-4479-b0bd-b08ee9ecbbee 4a44f9caaf2045d691354dce782ddb3e fa689ffe41cb46fb9a039bff9102debf - default default] [instance: 629a1603-6cd3-45a9-988c-c4a9939715c8] Get console output
2019-11-22 11:15:17.105 13856 INFO nova.privsep.libvirt [-] Ignored error while reading from instance console pty: [Errno 11] Resource temporarily unavailable
2019-11-22 11:15:57.921 12946 INFO nova.compute.manager [req-ef85edc7-6449-4a1c-bee2-0212add04ee5 4a44f9caaf2045d691354dce782ddb3e fa689ffe41cb46fb9a039bff9102debf - default default] [instance: 629a1603-6cd3-45a9-988c-c4a9939715c8] Get console output
2019-11-22 11:15:57.925 13856 INFO nova.privsep.libvirt [-] Ignored error while reading from instance console pty: [Errno 11] Resource temporarily unavailable